{
    "structureName": "Structure_0107_1656",
    "blocks": [
        {
            "x": 0,
            "y": 0,
            "z": 6,
            "blockName": "Grass"
        },
        {
            "x": 0,
            "y": 5,
            "z": 3,
            "blockName": "OakLeaves"
        },
        {
            "x": 0,
            "y": 6,
            "z": 3,
            "blockName": "OakLeaves"
        },
        {
            "x": 1,
            "y": 4,
            "z": 3,
            "blockName": "OakLeaves"
        },
        {
            "x": 1,
            "y": 4,
            "z": 4,
            "blockName": "OakLeaves"
        },
        {
            "x": 1,
            "y": 5,
            "z": 2,
            "blockName": "OakLeaves"
        },
        {
            "x": 1,
            "y": 5,
            "z": 3,
            "blockName": "OakLeaves"
        },
        {
            "x": 1,
            "y": 5,
            "z": 4,
            "blockName": "OakLeaves"
        },
        {
            "x": 1,
            "y": 6,
            "z": 2,
            "blockName": "OakLeaves"
        },
        {
            "x": 1,
            "y": 6,
            "z": 3,
            "blockName": "OakWood"
        },
        {
            "x": 1,
            "y": 6,
            "z": 4,
            "blockName": "OakLeaves"
        },
        {
            "x": 1,
            "y": 7,
            "z": 3,
            "blockName": "OakLeaves"
        },
        {
            "x": 2,
            "y": 3,
            "z": 3,
            "blockName": "OakWood"
        },
        {
            "x": 2,
            "y": 4,
            "z": 1,
            "blockName": "OakLeaves"
        },
        {
            "x": 2,
            "y": 4,
            "z": 2,
            "blockName": "OakLeaves"
        },
        {
            "x": 2,
            "y": 4,
            "z": 3,
            "blockName": "OakLeaves"
        },
        {
            "x": 2,
            "y": 4,
            "z": 4,
            "blockName": "OakLeaves"
        },
        {
            "x": 2,
            "y": 5,
            "z": 0,
            "blockName": "OakLeaves"
        },
        {
            "x": 2,
            "y": 5,
            "z": 1,
            "blockName": "OakLeaves"
        },
        {
            "x": 2,
            "y": 5,
            "z": 2,
            "blockName": "OakLeaves"
        },
        {
            "x": 2,
            "y": 5,
            "z": 3,
            "blockName": "OakLeaves"
        },
        {
            "x": 2,
            "y": 5,
            "z": 4,
            "blockName": "OakLeaves"
        },
        {
            "x": 2,
            "y": 5,
            "z": 5,
            "blockName": "OakLeaves"
        },
        {
            "x": 2,
            "y": 6,
            "z": 1,
            "blockName": "OakLeaves"
        },
        {
            "x": 2,
            "y": 6,
            "z": 2,
            "blockName": "OakLeaves"
        },
        {
            "x": 2,
            "y": 6,
            "z": 3,
            "blockName": "OakWood"
        },
        {
            "x": 2,
            "y": 6,
            "z": 4,
            "blockName": "OakLeaves"
        },
        {
            "x": 2,
            "y": 7,
            "z": 3,
            "blockName": "OakLeaves"
        },
        {
            "x": 3,
            "y": 0,
            "z": 3,
            "blockName": "OakWood"
        },
        {
            "x": 3,
            "y": 1,
            "z": 3,
            "blockName": "OakWood"
        },
        {
            "x": 3,
            "y": 2,
            "z": 3,
            "blockName": "OakWood"
        },
        {
            "x": 3,
            "y": 3,
            "z": 1,
            "blockName": "OakLeaves"
        },
        {
            "x": 3,
            "y": 3,
            "z": 2,
            "blockName": "OakLeaves"
        },
        {
            "x": 3,
            "y": 3,
            "z": 3,
            "blockName": "OakWood"
        },
        {
            "x": 3,
            "y": 3,
            "z": 4,
            "blockName": "OakLeaves"
        },
        {
            "x": 3,
            "y": 4,
            "z": 0,
            "blockName": "OakLeaves"
        },
        {
            "x": 3,
            "y": 4,
            "z": 1,
            "blockName": "OakWood"
        },
        {
            "x": 3,
            "y": 4,
            "z": 2,
            "blockName": "OakWood"
        },
        {
            "x": 3,
            "y": 4,
            "z": 3,
            "blockName": "OakWood"
        },
        {
            "x": 3,
            "y": 4,
            "z": 4,
            "blockName": "OakLeaves"
        },
        {
            "x": 3,
            "y": 4,
            "z": 5,
            "blockName": "OakLeaves"
        },
        {
            "x": 3,
            "y": 5,
            "z": 0,
            "blockName": "OakLeaves"
        },
        {
            "x": 3,
            "y": 5,
            "z": 1,
            "blockName": "OakLeaves"
        },
        {
            "x": 3,
            "y": 5,
            "z": 2,
            "blockName": "OakLeaves"
        },
        {
            "x": 3,
            "y": 5,
            "z": 3,
            "blockName": "OakWood"
        },
        {
            "x": 3,
            "y": 5,
            "z": 4,
            "blockName": "OakWood"
        },
        {
            "x": 3,
            "y": 5,
            "z": 5,
            "blockName": "OakWood"
        },
        {
            "x": 3,
            "y": 5,
            "z": 6,
            "blockName": "OakLeaves"
        },
        {
            "x": 3,
            "y": 6,
            "z": 0,
            "blockName": "OakLeaves"
        },
        {
            "x": 3,
            "y": 6,
            "z": 1,
            "blockName": "OakLeaves"
        },
        {
            "x": 3,
            "y": 6,
            "z": 2,
            "blockName": "OakLeaves"
        },
        {
            "x": 3,
            "y": 6,
            "z": 3,
            "blockName": "OakWood"
        },
        {
            "x": 3,
            "y": 6,
            "z": 4,
            "blockName": "OakLeaves"
        },
        {
            "x": 3,
            "y": 6,
            "z": 5,
            "blockName": "OakLeaves"
        },
        {
            "x": 3,
            "y": 7,
            "z": 2,
            "blockName": "OakLeaves"
        },
        {
            "x": 3,
            "y": 7,
            "z": 3,
            "blockName": "OakWood"
        },
        {
            "x": 3,
            "y": 7,
            "z": 4,
            "blockName": "OakLeaves"
        },
        {
            "x": 3,
            "y": 7,
            "z": 5,
            "blockName": "OakLeaves"
        },
        {
            "x": 3,
            "y": 8,
            "z": 3,
            "blockName": "OakLeaves"
        },
        {
            "x": 4,
            "y": 3,
            "z": 2,
            "blockName": "OakLeaves"
        },
        {
            "x": 4,
            "y": 3,
            "z": 3,
            "blockName": "OakLeaves"
        },
        {
            "x": 4,
            "y": 4,
            "z": 1,
            "blockName": "OakLeaves"
        },
        {
            "x": 4,
            "y": 4,
            "z": 2,
            "blockName": "OakLeaves"
        },
        {
            "x": 4,
            "y": 4,
            "z": 3,
            "blockName": "OakLeaves"
        },
        {
            "x": 4,
            "y": 4,
            "z": 4,
            "blockName": "OakLeaves"
        },
        {
            "x": 4,
            "y": 5,
            "z": 1,
            "blockName": "OakLeaves"
        },
        {
            "x": 4,
            "y": 5,
            "z": 2,
            "blockName": "OakLeaves"
        },
        {
            "x": 4,
            "y": 5,
            "z": 3,
            "blockName": "OakLeaves"
        },
        {
            "x": 4,
            "y": 5,
            "z": 4,
            "blockName": "OakLeaves"
        },
        {
            "x": 4,
            "y": 5,
            "z": 5,
            "blockName": "OakLeaves"
        },
        {
            "x": 4,
            "y": 6,
            "z": 1,
            "blockName": "OakLeaves"
        },
        {
            "x": 4,
            "y": 6,
            "z": 2,
            "blockName": "OakLeaves"
        },
        {
            "x": 4,
            "y": 6,
            "z": 3,
            "blockName": "OakLeaves"
        },
        {
            "x": 4,
            "y": 6,
            "z": 4,
            "blockName": "OakLeaves"
        },
        {
            "x": 4,
            "y": 6,
            "z": 5,
            "blockName": "OakLeaves"
        },
        {
            "x": 4,
            "y": 7,
            "z": 3,
            "blockName": "OakLeaves"
        },
        {
            "x": 4,
            "y": 7,
            "z": 4,
            "blockName": "OakLeaves"
        },
        {
            "x": 5,
            "y": 4,
            "z": 3,
            "blockName": "OakLeaves"
        },
        {
            "x": 5,
            "y": 5,
            "z": 3,
            "blockName": "OakLeaves"
        },
        {
            "x": 5,
            "y": 5,
            "z": 4,
            "blockName": "OakLeaves"
        },
        {
            "x": 5,
            "y": 6,
            "z": 3,
            "blockName": "OakLeaves"
        },
        {
            "x": 5,
            "y": 6,
            "z": 4,
            "blockName": "OakLeaves"
        },
        {
            "x": 5,
            "y": 8,
            "z": 0,
            "blockName": "Grass"
        }
    ]
}