{
    "structureName": "Structure_0106_2256",
    "blocks": [
        {
            "x": 0,
            "y": 0,
            "z": 0,
            "blockName": "Grass"
        },
        {
            "x": 0,
            "y": 3,
            "z": 1,
            "blockName": "Leaves"
        },
        {
            "x": 0,
            "y": 4,
            "z": 0,
            "blockName": "Leaves"
        },
        {
            "x": 0,
            "y": 4,
            "z": 1,
            "blockName": "Leaves"
        },
        {
            "x": 0,
            "y": 4,
            "z": 2,
            "blockName": "Leaves"
        },
        {
            "x": 0,
            "y": 5,
            "z": 0,
            "blockName": "FlatSnow"
        },
        {
            "x": 0,
            "y": 5,
            "z": 1,
            "blockName": "Leaves"
        },
        {
            "x": 0,
            "y": 5,
            "z": 2,
            "blockName": "FlatSnow"
        },
        {
            "x": 0,
            "y": 6,
            "z": 1,
            "blockName": "FlatSnow"
        },
        {
            "x": 1,
            "y": 0,
            "z": 1,
            "blockName": "Wood"
        },
        {
            "x": 1,
            "y": 1,
            "z": 1,
            "blockName": "Wood"
        },
        {
            "x": 1,
            "y": 2,
            "z": 1,
            "blockName": "Wood"
        },
        {
            "x": 1,
            "y": 3,
            "z": 0,
            "blockName": "Leaves"
        },
        {
            "x": 1,
            "y": 3,
            "z": 1,
            "blockName": "Wood"
        },
        {
            "x": 1,
            "y": 3,
            "z": 2,
            "blockName": "Leaves"
        },
        {
            "x": 1,
            "y": 4,
            "z": 0,
            "blockName": "Leaves"
        },
        {
            "x": 1,
            "y": 4,
            "z": 1,
            "blockName": "Wood"
        },
        {
            "x": 1,
            "y": 4,
            "z": 2,
            "blockName": "Leaves"
        },
        {
            "x": 1,
            "y": 5,
            "z": 0,
            "blockName": "Leaves"
        },
        {
            "x": 1,
            "y": 5,
            "z": 1,
            "blockName": "Wood"
        },
        {
            "x": 1,
            "y": 5,
            "z": 2,
            "blockName": "Leaves"
        },
        {
            "x": 1,
            "y": 6,
            "z": 0,
            "blockName": "FlatSnow"
        },
        {
            "x": 1,
            "y": 6,
            "z": 1,
            "blockName": "Leaves"
        },
        {
            "x": 1,
            "y": 6,
            "z": 2,
            "blockName": "FlatSnow"
        },
        {
            "x": 1,
            "y": 7,
            "z": 1,
            "blockName": "Leaves"
        },
        {
            "x": 1,
            "y": 8,
            "z": 1,
            "blockName": "FlatSnow"
        },
        {
            "x": 2,
            "y": 3,
            "z": 1,
            "blockName": "Leaves"
        },
        {
            "x": 2,
            "y": 4,
            "z": 0,
            "blockName": "Leaves"
        },
        {
            "x": 2,
            "y": 4,
            "z": 1,
            "blockName": "Leaves"
        },
        {
            "x": 2,
            "y": 4,
            "z": 2,
            "blockName": "Leaves"
        },
        {
            "x": 2,
            "y": 5,
            "z": 0,
            "blockName": "FlatSnow"
        },
        {
            "x": 2,
            "y": 5,
            "z": 1,
            "blockName": "Leaves"
        },
        {
            "x": 2,
            "y": 5,
            "z": 2,
            "blockName": "FlatSnow"
        },
        {
            "x": 2,
            "y": 6,
            "z": 1,
            "blockName": "FlatSnow"
        },
        {
            "x": 2,
            "y": 8,
            "z": 2,
            "blockName": "Grass"
        }
    ]
}