{
    "structureName": "Structure_0107_1650",
    "blocks": [
        {
            "x": 0,
            "y": 0,
            "z": 3,
            "blockName": "Grass"
        },
        {
            "x": 0,
            "y": 7,
            "z": 2,
            "blockName": "SpruceLeaves"
        },
        {
            "x": 0,
            "y": 8,
            "z": 1,
            "blockName": "SpruceLeaves"
        },
        {
            "x": 0,
            "y": 8,
            "z": 2,
            "blockName": "SpruceLeaves"
        },
        {
            "x": 0,
            "y": 8,
            "z": 3,
            "blockName": "SpruceLeaves"
        },
        {
            "x": 0,
            "y": 9,
            "z": 1,
            "blockName": "SpruceLeaves"
        },
        {
            "x": 0,
            "y": 9,
            "z": 2,
            "blockName": "SpruceLeaves"
        },
        {
            "x": 0,
            "y": 9,
            "z": 3,
            "blockName": "SpruceLeaves"
        },
        {
            "x": 0,
            "y": 10,
            "z": 1,
            "blockName": "FlatSnow"
        },
        {
            "x": 0,
            "y": 10,
            "z": 2,
            "blockName": "SpruceLeaves"
        },
        {
            "x": 0,
            "y": 10,
            "z": 3,
            "blockName": "FlatSnow"
        },
        {
            "x": 0,
            "y": 11,
            "z": 2,
            "blockName": "FlatSnow"
        },
        {
            "x": 1,
            "y": 0,
            "z": 2,
            "blockName": "SpruceWood"
        },
        {
            "x": 1,
            "y": 1,
            "z": 2,
            "blockName": "SpruceWood"
        },
        {
            "x": 1,
            "y": 2,
            "z": 2,
            "blockName": "SpruceWood"
        },
        {
            "x": 1,
            "y": 3,
            "z": 2,
            "blockName": "SpruceWood"
        },
        {
            "x": 1,
            "y": 4,
            "z": 2,
            "blockName": "SpruceWood"
        },
        {
            "x": 1,
            "y": 5,
            "z": 2,
            "blockName": "SpruceWood"
        },
        {
            "x": 1,
            "y": 6,
            "z": 2,
            "blockName": "SpruceWood"
        },
        {
            "x": 1,
            "y": 7,
            "z": 1,
            "blockName": "SpruceLeaves"
        },
        {
            "x": 1,
            "y": 7,
            "z": 2,
            "blockName": "SpruceWood"
        },
        {
            "x": 1,
            "y": 7,
            "z": 3,
            "blockName": "SpruceLeaves"
        },
        {
            "x": 1,
            "y": 8,
            "z": 1,
            "blockName": "SpruceLeaves"
        },
        {
            "x": 1,
            "y": 8,
            "z": 2,
            "blockName": "SpruceWood"
        },
        {
            "x": 1,
            "y": 8,
            "z": 3,
            "blockName": "SpruceLeaves"
        },
        {
            "x": 1,
            "y": 9,
            "z": 1,
            "blockName": "SpruceLeaves"
        },
        {
            "x": 1,
            "y": 9,
            "z": 2,
            "blockName": "SpruceWood"
        },
        {
            "x": 1,
            "y": 9,
            "z": 3,
            "blockName": "SpruceLeaves"
        },
        {
            "x": 1,
            "y": 10,
            "z": 1,
            "blockName": "SpruceLeaves"
        },
        {
            "x": 1,
            "y": 10,
            "z": 2,
            "blockName": "SpruceWood"
        },
        {
            "x": 1,
            "y": 10,
            "z": 3,
            "blockName": "SpruceLeaves"
        },
        {
            "x": 1,
            "y": 11,
            "z": 1,
            "blockName": "FlatSnow"
        },
        {
            "x": 1,
            "y": 11,
            "z": 2,
            "blockName": "SpruceLeaves"
        },
        {
            "x": 1,
            "y": 11,
            "z": 3,
            "blockName": "FlatSnow"
        },
        {
            "x": 1,
            "y": 12,
            "z": 2,
            "blockName": "FlatSnow"
        },
        {
            "x": 2,
            "y": 7,
            "z": 2,
            "blockName": "SpruceLeaves"
        },
        {
            "x": 2,
            "y": 8,
            "z": 1,
            "blockName": "SpruceLeaves"
        },
        {
            "x": 2,
            "y": 8,
            "z": 2,
            "blockName": "SpruceLeaves"
        },
        {
            "x": 2,
            "y": 8,
            "z": 3,
            "blockName": "SpruceLeaves"
        },
        {
            "x": 2,
            "y": 9,
            "z": 1,
            "blockName": "SpruceLeaves"
        },
        {
            "x": 2,
            "y": 9,
            "z": 2,
            "blockName": "SpruceLeaves"
        },
        {
            "x": 2,
            "y": 9,
            "z": 3,
            "blockName": "SpruceLeaves"
        },
        {
            "x": 2,
            "y": 10,
            "z": 1,
            "blockName": "FlatSnow"
        },
        {
            "x": 2,
            "y": 10,
            "z": 2,
            "blockName": "SpruceLeaves"
        },
        {
            "x": 2,
            "y": 10,
            "z": 3,
            "blockName": "FlatSnow"
        },
        {
            "x": 2,
            "y": 11,
            "z": 2,
            "blockName": "FlatSnow"
        },
        {
            "x": 2,
            "y": 12,
            "z": 0,
            "blockName": "Grass"
        }
    ]
}